<?xml version="1.0" ?>
<!-- =================================================================================== -->
<!-- |    This document was autogenerated by xacro from kuka_lwr_arm.urdf.xacro        | -->
<!-- |    EDITING THIS FILE BY HAND IS NOT RECOMMENDED                                 | -->
<!-- =================================================================================== -->
<robot name="kuka_lwr">
  <!-- right is either 1 (for right arm) or -1 (for left arm) -->
  <link name="calib_kuka_arm_base_link">
    <inertial>
      <mass value="0"/>
      <!-- static base, disable dynamics for this link -->
      <origin rpy="0 0 0" xyz="0 0 0.055"/>
      <inertia ixx="0.00381666666667" ixy="0" ixz="0" iyy="0.0036" iyz="0" izz="0.00381666666667"/>
    </inertial>
    <visual>
      <origin rpy="0 0 0" xyz="0 0 0"/>
      <geometry>
        <mesh filename="meshes_arm/arm_base.stl"/>
      </geometry>
      <material name="Orange"/>
    </visual>
    <collision>
      <origin rpy="0 0 0" xyz="0 0 0"/>
      <geometry>
        <mesh filename="meshes_arm/convex/arm_base_convex.stl"/>
      </geometry>
    </collision>
  </link>
  <joint name="kuka_arm_0_joint" type="revolute">
    <origin rpy="0 0 0" xyz="0 0 0.11"/>
    <axis xyz="0 0 1"/>
    <limit effort="204" lower="-2.96705972839" upper="2.96705972839" velocity="1.91986217719"/>
    <dynamics damping="0.1"/>
    <parent link="calib_kuka_arm_base_link"/>
    <child link="panda_link1"/>
  </joint>
  <link name="panda_link1">
    <inertial>
      <mass value="2.0"/>
      <origin rpy="0 0 0" xyz="0 0.04 0.130"/>
      <inertia ixx="0.0136666666667" ixy="0" ixz="0" iyy="0.0118666666667" iyz="0" izz="0.003"/>
    </inertial>
    <visual>
      <origin rpy="0 0 3.14159265359" xyz="0 0 0"/>
      <geometry>
        <mesh filename="meshes_arm/arm_segment_a.stl"/>
      </geometry>
      <material name="Orange"/>
    </visual>
    <collision>
      <origin rpy="0 0 3.14159265359" xyz="0 0 0"/>
      <geometry>
        <mesh filename="meshes_arm/convex/arm_segment_a_convex.stl"/>
      </geometry>
    </collision>
  </link>
  <transmission name="kuka_arm_0_trans" type="pr2_mechanism_model/SimpleTransmission">
    <actuator name="kuka_arm_0_motor"/>
    <joint name="kuka_arm_0_joint"/>
    <mechanicalReduction>1.0</mechanicalReduction>
  </transmission>
  <joint name="kuka_arm_1_joint" type="revolute">
    <origin rpy="0 0 0" xyz="0 0 0.20"/>
    <axis xyz="0 -1 0"/>
    <!--limit lower="${-120 * M_PI / 180}" upper="${120 * M_PI / 180}"
             effort="306" velocity="${arm_velocity_scale_factor * 110 * M_PI / 180}" /-->
    <!-- nalt: Reduced limits to avoid contact with table - kinda hacky, should not be done here -->
    <limit effort="306" lower="-1.57079632679" upper="1.57079632679" velocity="1.91986217719"/>
    <dynamics damping="0.1"/>
    <parent link="panda_link1"/>
    <child link="panda_link2"/>
  </joint>
  <link name="panda_link2">
    <inertial>
      <mass value="2.0"/>
      <origin rpy="0 0 0" xyz="0 -0.04 0.07"/>
      <inertia ixx="0.0136666666667" ixy="0" ixz="0" iyy="0.0118666666667" iyz="0" izz="0.003"/>
    </inertial>
    <visual>
      <origin rpy="3.14159265359 0 3.14159265359" xyz="0 0 0.2"/>
      <geometry>
        <mesh filename="meshes_arm/arm_segment_b.stl"/>
      </geometry>
      <material name="Orange"/>
    </visual>
    <collision>
      <origin rpy="3.14159265359 0 3.14159265359" xyz="0 0 0.2"/>
      <geometry>
        <mesh filename="meshes_arm/convex/arm_segment_b_convex.stl"/>
      </geometry>
    </collision>
  </link>
  <transmission name="kuka_arm_1_trans" type="pr2_mechanism_model/SimpleTransmission">
    <actuator name="kuka_arm_1_motor"/>
    <joint name="kuka_arm_1_joint"/>
    <mechanicalReduction>1.0</mechanicalReduction>
  </transmission>
  <joint name="kuka_arm_2_joint" type="revolute">
    <origin rpy="0 0 0" xyz="0 0 0.20"/>
    <axis xyz="0 0 1"/>
    <limit effort="204" lower="-2.96705972839" upper="2.96705972839" velocity="2.26892802759"/>
    <dynamics damping="0.1"/>
    <parent link="panda_link2"/>
    <child link="panda_link3"/>
  </joint>
  <link name="panda_link3">
    <inertial>
      <mass value="2.0"/>
      <origin rpy="0 0 0" xyz="0 -0.04 0.130"/>
      <inertia ixx="0.0136666666667" ixy="0" ixz="0" iyy="0.0118666666667" iyz="0" izz="0.003"/>
    </inertial>
    <visual>
      <origin rpy="0 0 0" xyz="0 0 0"/>
      <geometry>
        <mesh filename="meshes_arm/arm_segment_a.stl"/>
      </geometry>
      <material name="Orange"/>
    </visual>
    <collision>
      <origin rpy="0 0 0" xyz="0 0 0"/>
      <geometry>
        <mesh filename="meshes_arm/convex/arm_segment_a_convex.stl"/>
      </geometry>
    </collision>
  </link>
  <transmission name="kuka_arm_2_trans" type="pr2_mechanism_model/SimpleTransmission">
    <actuator name="kuka_arm_2_motor"/>
    <joint name="kuka_arm_2_joint"/>
    <mechanicalReduction>1.0</mechanicalReduction>
  </transmission>
  <joint name="kuka_arm_3_joint" type="revolute">
    <origin rpy="0 0 0" xyz="0 0 0.20"/>
    <axis xyz="0 1 0"/>
    <limit effort="306" lower="-2.09439510239" upper="2.09439510239" velocity="2.26892802759"/>
    <dynamics damping="0.1"/>
    <parent link="panda_link3"/>
    <child link="panda_link4"/>
  </joint>
  <link name="panda_link4">
    <inertial>
      <mass value="2.0"/>
      <origin rpy="0 0 0" xyz="0 0.04 0.07"/>
      <inertia ixx="0.0136666666667" ixy="0" ixz="0" iyy="0.0118666666667" iyz="0" izz="0.003"/>
    </inertial>
    <visual>
      <origin rpy="0 3.14159265359 3.14159265359" xyz="0 0 0.2"/>
      <geometry>
        <mesh filename="meshes_arm/arm_segment_b.stl"/>
      </geometry>
      <material name="Orange"/>
    </visual>
    <collision>
      <origin rpy="0 3.14159265359 3.14159265359" xyz="0 0 0.2"/>
      <geometry>
        <mesh filename="meshes_arm/convex/arm_segment_b_convex.stl"/>
      </geometry>
    </collision>
  </link>
  <transmission name="kuka_arm_3_trans" type="pr2_mechanism_model/SimpleTransmission">
    <actuator name="kuka_arm_3_motor"/>
    <joint name="kuka_arm_3_joint"/>
    <mechanicalReduction>1.0</mechanicalReduction>
  </transmission>
  <joint name="kuka_arm_4_joint" type="revolute">
    <origin rpy="0 0 0" xyz="0 0 0.20"/>
    <axis xyz="0 0 1"/>
    <limit effort="204" lower="-2.96705972839" upper="2.96705972839" velocity="2.26892802759"/>
    <dynamics damping="0.1"/>
    <parent link="panda_link4"/>
    <child link="panda_link5"/>
  </joint>
  <link name="panda_link5">
    <inertial>
      <mass value="2.0"/>
      <origin rpy="0 0 0" xyz="0 0.02 0.124"/>
      <inertia ixx="0.0126506666667" ixy="0" ixz="0" iyy="0.0108506666667" iyz="0" izz="0.003"/>
    </inertial>
    <visual>
      <origin rpy="0 0 3.14159265359" xyz="0 0 0"/>
      <geometry name="kuka_arm_5_geom">
        <mesh filename="meshes_arm/arm_segment_last.stl"/>
      </geometry>
      <material name="Orange"/>
    </visual>
    <collision>
      <origin rpy="0 0 3.14159265359" xyz="0 0 0"/>
      <geometry>
        <mesh filename="meshes_arm/convex/arm_segment_last_convex.stl"/>
      </geometry>
    </collision>
  </link>
  <transmission name="kuka_arm_4_trans" type="pr2_mechanism_model/SimpleTransmission">
    <actuator name="kuka_arm_4_motor"/>
    <joint name="kuka_arm_4_joint"/>
    <mechanicalReduction>1.0</mechanicalReduction>
  </transmission>
  <joint name="kuka_arm_5_joint" type="revolute">
    <origin rpy="0 0 0" xyz="0 0 0.19"/>
    <axis xyz="0 -1 0"/>
    <limit effort="306" lower="-2.09439510239" upper="2.09439510239" velocity="3.14159265359"/>
    <dynamics damping="0.1"/>
    <parent link="panda_link5"/>
    <child link="panda_link6"/>
  </joint>
  <link name="panda_link6">
    <inertial>
      <mass value="2.0"/>
      <origin rpy="0 0 0" xyz="0 0 0"/>
      <inertia ixx="0.00520833333333" ixy="0" ixz="0" iyy="0.00520833333333" iyz="0" izz="0.00520833333333"/>
    </inertial>
    <visual>
      <origin rpy="0 0 3.14159265359" xyz="0 0 0"/>
      <geometry>
        <mesh filename="meshes_arm/arm_wrist.stl"/>
      </geometry>
      <material name="Grey"/>
    </visual>
    <collision>
      <origin rpy="0 0 3.14159265359" xyz="0 0 0"/>
      <geometry>
        <mesh filename="meshes_arm/convex/arm_wrist_convex.stl"/>
      </geometry>
    </collision>
  </link>
  <transmission name="kuka_arm_5_trans" type="pr2_mechanism_model/SimpleTransmission">
    <actuator name="kuka_arm_5_motor"/>
    <joint name="kuka_arm_5_joint"/>
    <mechanicalReduction>1.0</mechanicalReduction>
  </transmission>
  <joint name="kuka_arm_6_joint" type="revolute">
    <origin rpy="0 0 0" xyz="0 0 0.078"/>
    <axis xyz="0 0 1"/>
    <limit effort="204" lower="-2.96705972839" upper="2.96705972839" velocity="3.14159265359"/>
    <dynamics damping="0.1"/>
    <parent link="panda_link6"/>
    <child link="panda_link7"/>
  </joint>
  <link name="panda_link7">
    <inertial>
      <mass value="2.0"/>
      <origin xyz="0 0 0"/>
      <inertia ixx="0.000833333333333" ixy="0" ixz="0" iyy="0.000833333333333" iyz="0" izz="0.000833333333333"/>
    </inertial>
    <visual>
      <origin rpy="0 0 3.14159265359" xyz="0 0 0"/>
      <geometry>
        <mesh filename="meshes_arm/arm_flanche.stl"/>
      </geometry>
      <material name="Grey"/>
    </visual>
    <collision>
      <origin rpy="0 0 3.14159265359" xyz="0 0 0"/>
      <geometry>
        <mesh filename="meshes_arm/convex/arm_flanche_convex.stl"/>
      </geometry>
    </collision>
  </link>
  <transmission name="kuka_arm_6_trans" type="pr2_mechanism_model/SimpleTransmission">
    <actuator name="kuka_arm_6_motor"/>
    <joint name="kuka_arm_6_joint"/>
    <mechanicalReduction>1.0</mechanicalReduction>
  </transmission>

  <joint name="panda_hand_joint" type="fixed">
    <parent link="panda_link7" />
    <child link="panda_hand" />
    <origin rpy="0 0 0" xyz="0 0 0" />
  </joint>
  <link name="panda_hand">
    <inertial>
      <origin rpy="0 0 0" xyz="0 0 0.04" />
      <mass value=".81" />
      <inertia ixx="0.1" ixy="0" ixz="0" iyy="0.1" iyz="0" izz="0.1" />
    </inertial>
    <visual>
      <geometry>
        <mesh filename="meshes_arm/hand.obj" />
      </geometry>
      <material name="panda_white" />
    </visual>
    <collision>
      <geometry>
        <mesh filename="meshes_arm/hand.obj" />
      </geometry>
      <material name="panda_white" />
    </collision>
  </link>
  <link name="panda_leftfinger">
    <contact>
      <friction_anchor />
      <stiffness value="30000.0" />
      <damping value="1000.0" />
      <spinning_friction value="0.1" />
      <lateral_friction value="1.0" />
    </contact>
    <inertial>
      <origin rpy="0 0 0" xyz="0 0.01 0.02" />
      <mass value="0.1" />
      <inertia ixx="0.1" ixy="0" ixz="0" iyy="0.1" iyz="0" izz="0.1" />
    </inertial>
    <visual>
      <geometry>
        <mesh filename="meshes_arm/finger.obj" />
      </geometry>
      <material name="panda_white" />
    </visual>
    <collision>
      <geometry>
        <mesh filename="meshes_arm/finger.obj" />
      </geometry>
      <material name="panda_white" />
    </collision>
  </link>
  <link name="panda_rightfinger">
    <contact>
      <friction_anchor />
      <stiffness value="30000.0" />
      <damping value="1000.0" />
      <spinning_friction value="0.1" />
      <lateral_friction value="1.0" />
    </contact>

    <inertial>
      <origin rpy="0 0 0" xyz="0 -0.01 0.02" />
      <mass value="0.1" />
      <inertia ixx="0.1" ixy="0" ixz="0" iyy="0.1" iyz="0" izz="0.1" />
    </inertial>
    <visual>
      <origin rpy="0 0 3.14159265359" xyz="0 0 0" />
      <geometry>
        <mesh filename="meshes_arm/finger.obj" />
      </geometry>
      <material name="panda_white" />
    </visual>
    <collision>
      <origin rpy="0 0 3.14159265359" xyz="0 0 0" />
      <geometry>
        <mesh filename="meshes_arm/finger.obj" />
      </geometry>
      <material name="panda_white" />
    </collision>
  </link>
  <joint name="panda_finger_joint1" type="prismatic">
    <parent link="panda_hand" />
    <child link="panda_leftfinger" />
    <origin rpy="0 0 0" xyz="0 0 0.0584" />
    <axis xyz="0 1 0" />
    <limit effort="20" lower="0.0" upper="0.04" velocity="0.2" />
  </joint>
  <joint name="panda_finger_joint2" type="prismatic">
    <parent link="panda_hand" />
    <child link="panda_rightfinger" />
    <origin rpy="0 0 0" xyz="0 0 0.0584" />
    <axis xyz="0 -1 0" />
    <limit effort="20" lower="0.0" upper="0.04" velocity="0.2" />
    <mimic joint="panda_finger_joint1" />
  </joint>
  <link name="panda_grasptarget">
    <inertial>
      <origin rpy="0 0 0" xyz="0 0 0" />
      <mass value="0.0" />
      <inertia ixx="0.1" ixy="0" ixz="0" iyy="0.1" iyz="0" izz="0.1" />
    </inertial>
  </link>
  <joint name="panda_grasptarget_hand" type="fixed">
    <parent link="panda_hand" />
    <child link="panda_grasptarget" />
    <origin rpy="0 0 0" xyz="0 0 0.105" />
  </joint>

</robot>
